Workbook
Name ScenarioIndex: 'Cashflows'!$C$5
Name DiscountRate: 'Model Inputs'!$C18
Name License_Y1: 'Model Inputs'!$C143
Name Impl_Y1: 'Model Inputs'!$C150
Name License_Y2: 'Model Inputs'!$C144
Name Impl_Y2: 'Model Inputs'!$C151
Name License_Y3: 'Model Inputs'!$C145
Name Impl_Y3: 'Model Inputs'!$C152
Name License_Y4: 'Model Inputs'!$C146
Name Impl_Y4: 'Model Inputs'!$C153
Name License_Y5: 'Model Inputs'!$C147
Name Impl_Y5: 'Model Inputs'!$C154

Sheet Cover Page
B5: Return on Investment Calculator
B7: Value Consulting - Business Case
B10: Client Name: | C10: SeABank — Retail Banking Division
B12: Date: | C12: 2026-04-06
B14: Currency: | C14: USD
B16: Analysis Period: | C16: 5 Years
B18: Selected Scenario: | C18: Moderate
B20: Discount Rate: | C20: 10.0%
B24: DATA SOURCE LEGEND
B26: Green | C26: From transcript/client data
B27: Yellow | C27: Estimate - requires validation
B28: Blue | C28: Backbase benchmark
B29: Red border | C29: Low confidence - critical validation

Sheet Instructions
B2: ROI Model Instructions
B5: THIS IS A LIVE MODEL — all calculations use Excel formulas.
B6: Changing any input on 'Model Inputs' will automatically recalculate all sheets.
B8: SCENARIO SWITCHING
B9: • Go to 'Model Inputs' sheet, cell C5
B10: • Select: 1 = Conservative, 2 = Moderate, 3 = Aggressive
B11: • All curves, impacts, and downstream calculations will update instantly
B13: EDITING INPUTS
B14: • Blue-shaded cells on 'Model Inputs' are editable — change volumes, rates, costs
B15: • Yellow cells are estimates that should be validated with client data
B16: • Green cells are from transcript — highest confidence
B18: SHEET ARCHITECTURE
... B28: • LOW - Estimate based on typical patterns - REQUIRES VALIDATION

Sheet Table of Contents
B3: Table of Contents
B5: Input Layer | C5: Model Inputs — editable parameters
C6: Scenario Data — Conservative / Moderate / Aggressive
B7: Calculation | C7: Servicing Detail — task-level breakdown
C8: Lever: L1: Digital Onboarding Funnel Recovery
C9: Lever: L2: Onboarding Cycle Time Acceleration
C10: Lever: L3: Call Center Cost Deflection
C11: Lever: L4: Branch-to-Digital Servicing Migration
C12: Lever: L5: Digital Banking Adoption Acceleration
C13: Lever: L6: Back Office STP & Workaround Elimination
C14: Lever: L7: Digital Lending Pre-Approved Origination
C15: Lever: Loyalty, Retention & Product Penetration
C16: Cashflows — 5-year projection
B17: Output Layer | C17: Results Dashboard — NPV, IRR, Payback, ROI
B18: Reference | C18: Assumptions Register
C19: Data Gaps for Validation

Sheet Cashflows
B1: 5 Year Cashflows & ROI
B3: All values are live formulas. Change the scenario below — Journey Analysis and Cashflows update automatically.
B4: SCENARIO SELECTOR
B5: Active Scenario (1=Conservative, 2=Moderate, 3=Aggressive) | C5: 2
B6: =IF(C5=1,"Conservative — slower adoption, cautious assumptions",IF(C5=2,"Moderate — base case, phased rollout","Aggressive — fast adoption, full benefit"))
C8: Year 1 | D8: Year 2 | E8: Year 3 | F8: Year 4 | G8: Year 5 | H8: Total
B9: CASH INFLOWS (Benefits)
B10: L1: Digital Onboarding Funnel Recovery | C10: ='Journey Analysis'!C30*'Model Inputs'!C160*'Model Inputs'!C166 | D10: ='Journey Analysis'!C30*'Model Inputs'!C161*'Model Inputs'!C167 | E10: ='Journey Analysis'!C30*'Model Inputs'!C162*'Model Inputs'!C168 | F10: ='Journey Analysis'!C30*'Model Inputs'!C163*'Model Inputs'!C169 | G10: ='Journey Analysis'!C30*'Model Inputs'!C164*'Model Inputs'!C170 | H10: =SUM(C10:G10)
B11: L2: Onboarding Cycle Time Acceleration | C11: ='Journey Analysis'!C46*'Model Inputs'!C160*'Model Inputs'!C166 | D11: ='Journey Analysis'!C46*'Model Inputs'!C161*'Model Inputs'!C167 | E11: ='Journey Analysis'!C46*'Model Inputs'!C162*'Model Inputs'!C168 | F11: ='Journey Analysis'!C46*'Model Inputs'!C163*'Model Inputs'!C169 | G11: ='Journey Analysis'!C46*'Model Inputs'!C164*'Model Inputs'!C170 | H11: =SUM(C11:G11)
B12: L3: Call Center Cost Deflection | C12: ='Journey Analysis'!C54*'Model Inputs'!C160*'Model Inputs'!C166 | D12: ='Journey Analysis'!C54*'Model Inputs'!C161*'Model Inputs'!C167 | E12: ='Journey Analysis'!C54*'Model Inputs'!C162*'Model Inputs'!C168 | F12: ='Journey Analysis'!C54*'Model Inputs'!C163*'Model Inputs'!C169 | G12: ='Journey Analysis'!C54*'Model Inputs'!C164*'Model Inputs'!C170 | H12: =SUM(C12:G12)
B13: L4: Branch-to-Digital Servicing Migration | C13: ='Journey Analysis'!C62*'Model Inputs'!C160*'Model Inputs'!C166 | D13: ='Journey Analysis'!C62*'Model Inputs'!C161*'Model Inputs'!C167 | E13: ='Journey Analysis'!C62*'Model Inputs'!C162*'Model Inputs'!C168 | F13: ='Journey Analysis'!C62*'Model Inputs'!C163*'Model Inputs'!C169 | G13: ='Journey Analysis'!C62*'Model Inputs'!C164*'Model Inputs'!C170 | H13: =SUM(C13:G13)
B14: L5: Digital Banking Adoption Acceleration | C14: ='Journey Analysis'!C78*'Model Inputs'!C160*'Model Inputs'!C166 | D14: ='Journey Analysis'!C78*'Model Inputs'!C161*'Model Inputs'!C167 | E14: ='Journey Analysis'!C78*'Model Inputs'!C162*'Model Inputs'!C168 | F14: ='Journey Analysis'!C78*'Model Inputs'!C163*'Model Inputs'!C169 | G14: ='Journey Analysis'!C78*'Model Inputs'!C164*'Model Inputs'!C170 | H14: =SUM(C14:G14)
B15: L6: Back Office STP & Workaround Elimination | C15: ='Journey Analysis'!C103*'Model Inputs'!C160*'Model Inputs'!C166 | D15: ='Journey Analysis'!C103*'Model Inputs'!C161*'Model Inputs'!C167 | E15: ='Journey Analysis'!C103*'Model Inputs'!C162*'Model Inputs'!C168 | F15: ='Journey Analysis'!C103*'Model Inputs'!C163*'Model Inputs'!C169 | G15: ='Journey Analysis'!C103*'Model Inputs'!C164*'Model Inputs'!C170 | H15: =SUM(C15:G15)
B16: L7: Digital Lending Pre-Approved Origination | C16: ='Journey Analysis'!C138*'Model Inputs'!C160*'Model Inputs'!C166 | D16: ='Journey Analysis'!C138*'Model Inputs'!C161*'Model Inputs'!C167 | E16: ='Journey Analysis'!C138*'Model Inputs'!C162*'Model Inputs'!C168 | F16: ='Journey Analysis'!C138*'Model Inputs'!C163*'Model Inputs'!C169 | G16: ='Journey Analysis'!C138*'Model Inputs'!C164*'Model Inputs'!C170 | H16: =SUM(C16:G16)
B17: Loyalty, Retention & Product Penetration | C17: ='Journey Analysis'!C164*'Model Inputs'!C160*'Model Inputs'!C166 | D17: ='Journey Analysis'!C164*'Model Inputs'!C161*'Model Inputs'!C167 | E17: ='Journey Analysis'!C164*'Model Inputs'!C162*'Model Inputs'!C168 | F17: ='Journey Analysis'!C164*'Model Inputs'!C163*'Model Inputs'!C169 | G17: ='Journey Analysis'!C164*'Model Inputs'!C164*'Model Inputs'!C170 | H17: =SUM(C17:G17)
B18: Servicing Growth Avoidance (FTE) | C18: ='Servicing Detail'!C61 | D18: ='Servicing Detail'!D61 | E18: ='Servicing Detail'!E61 | F18: ='Servicing Detail'!F61 | G18: ='Servicing Detail'!G61 | H18: =SUM(C18:G18)
B20: Total Cash Inflow | C20: =SUM(C10:C18) | D20: =SUM(D10:D18) | E20: =SUM(E10:E18) | F20: =SUM(F10:F18) | G20: =SUM(G10:G18) | H20: =SUM(H10:H18)
B23: CASH OUTFLOWS (Investment)
B24: License | C24: ='Model Inputs'!C143 | D24: ='Model Inputs'!C144 | E24: ='Model Inputs'!C145 | F24: ='Model Inputs'!C146 | G24: ='Model Inputs'!C147 | H24: =SUM(C24:G24)
B25: Implementation | C25: ='Model Inputs'!C150 | D25: ='Model Inputs'!C151 | E25: ='Model Inputs'!C152 | F25: ='Model Inputs'!C153 | G25: ='Model Inputs'!C154 | H25: =SUM(C25:G25)
B26: Total Cash Outflow | C26: =C24+C25 | D26: =D24+D25 | E26: =E24+E25 | F26: =F24+F25 | G26: =G24+G25 | H26: =H24+H25
B29: NET CASHFLOW | C29: =C20-C26 | D29: =D20-D26 | E29: =E20-E26 | F29: =F20-F26 | G29: =G20-G26 | H29: =SUM(C29:G29)
B30: Cumulative Cashflow | C30: =C29 | D30: =C30+D29 | E30: =D30+E29 | F30: =E30+F29 | G30: =F30+G29
B34: FINANCIAL METRICS
B35: Discount Rate (WACC) | C35: ='Model Inputs'!C18
B36: Total 5-Year Benefits | C36: =H20
B37: Total 5-Year Investment | C37: =H26
B38: Net Benefit | C38: =C36-C37
B39: ROI % | C39: =IFERROR((C36-C37)/C37,0)
B40: Net Present Value (NPV) | C40: =NPV(C35,C29:G29)
B41: Internal Rate of Return (IRR) | C41: =IFERROR(IRR(C29:G29),"N/A")
B42: Payback Period (Years) | C42: =IF(C30>=0,1-((C30-C29)/C29),IF(D30>=0,2-((D30-D29)/D29),IF(E30>=0,3-((E30-E29)/E29),IF(F30>=0,4-((F30-F29)/F29),IF(G30>=0,5-((G30-G29)/G29),"N/A")))))
B46: BENEFITS BY LEVER (Annual Steady State)
B48: Lever Group | C48: Lifecycle Stage | D48: Annual Benefit
B49: L1: Digital Onboarding Funnel Recovery | C49: Acquire | D49: ='Journey Analysis'!C30
B50: L2: Onboarding Cycle Time Acceleration | C50: Activate | D50: ='Journey Analysis'!C46
B51: L3: Call Center Cost Deflection | C51: Retain | D51: ='Journey Analysis'!C54
B52: L4: Branch-to-Digital Servicing Migration | C52: Retain | D52: ='Journey Analysis'!C62
B53: L5: Digital Banking Adoption Acceleration | C53: Activate | D53: ='Journey Analysis'!C78
B54: L6: Back Office STP & Workaround Elimination | C54: Activate | D54: ='Journey Analysis'!C103
...

Sheet Journey Analysis
B1: Journey Analysis — Benefit Calculation Chain
B2: Active Scenario: | C2: =IF('Cashflows'!$C$5=1,"Conservative",IF('Cashflows'!$C$5=2,"Moderate","Aggressive")) | D2: (Change on Cashflows sheet)
B3: Each lever: input factors → Baseline (formula) → × Backbase Impact → Annual Benefit. Change scenario on Cashflows to update scenario-linked impacts.
B5: L1: Digital Onboarding Funnel Recovery
B6: Evidence: E1, E2, E7
B7: Revenue Generation
B8: Digital Onboarding Funnel Recovery | D8: Revenue
B9: Factor | C9: Value | D9: Unit
B10: Annual Downloads | C10: ='Model Inputs'!C25 | D10: downloads/year
B11: Current Drop Rate | C11: ='Model Inputs'!C26 | D11: ratio
B12: Completion Rate | C12: ='Model Inputs'!C27 | D12: ratio
B13: Net Incremental Factor | C13: ='Model Inputs'!C28 | D13: ratio
B14: Revenue Per Customer | C14: ='Model Inputs'!C29 | D14: USD/year
B15: Baseline | C15: =C10 * C11 * C12 * C13 * C14 | D15: USD/year
B16: Backbase Impact | C16: ='Model Inputs'!C30 | D16: % of baseline captured by Backbase
B17: Annual Benefit | C17: =C15*C16 | D17: USD/year (scenario-adjusted)
B19: Cost Reduction
B20: Branch-to-Digital Onboarding Migration | D20: Cost
B21: Factor | C21: Value | D21: Unit
B22: Annual Branch Openings | C22: ='Model Inputs'!C35 | D22: accounts/year
B23: Time Saved Hours | C23: ='Model Inputs'!C36 | D23: hours
B24: Fte Rate | C24: ='Model Inputs'!C37 | D24: USD/hour
B25: Baseline | C25: =C22 * C23 * C24 | D25: USD/year
B26: Backbase Impact | C26: ='Model Inputs'!C38 | D26: % of baseline captured by Backbase
B27: Annual Benefit | C27: =C25*C26 | D27: USD/year (scenario-adjusted)
B30: Total: L1: Digital Onboarding Funnel Recovery | C30: =C17+C27
B33: L2: Onboarding Cycle Time Acceleration
B34: Evidence: E3, E8
B35: Cost Reduction
B36: Onboarding Processing Cost Reduction via STP | D36: Cost
B37: Factor | C37: Value | D37: Unit
B38: Annual Applications | C38: ='Model Inputs'!C45 | D38: applications/year
B39: Manual Processing Hours | C39: ='Model Inputs'!C46 | D39: hours
B40: Fte Rate | C40: ='Model Inputs'!C47 | D40: USD/hour
B41: Baseline | C41: =C38 * C39 * C40 | D41: USD/year
B42: Backbase Impact | C42: ='Model Inputs'!C48 | D42: % of baseline captured by Backbase
B43: Annual Benefit | C43: =C41*C42 | D43: USD/year (scenario-adjusted)
B46: Total: L2: Onboarding Cycle Time Acceleration | C46: =C43
B49: L3: Call Center Cost Deflection
B50: Evidence: E4, E5
...

Sheet Servicing Detail
B1: Customer Servicing — Channel Analysis
B3: Vol Saving = Baseline × Vol Deflection. Time Saving = Remaining Vol × Time × Time Reduction × Rate. Total = Vol + Time Saving.
B5: Task | C5: Volume | D5: Time (hrs) | E5: Rate | F5: Baseline | G5: Vol Deflection | H5: Time Reduction | I5: Vol Saving | J5: Time Saving | K5: Total Saved | L5: Source
B6: Evidence: E4, E5
B8: Call Center
B9: Accounts & Balance Inquiries | C9: 18720 | D9: 0.05 | E9: 7.83 | F9: =C9*D9*E9 | G9: 0.7 | H9: 0.2 | I9: =F9*G9 | J9: =C9*(1-G9)*D9*H9*E9 | K9: =I9+J9 | L9: CLIENT DATA — 1,560/month x 12. Routine balance checks.
B10: Card Services (Block/PIN/Limit) | C10: 8160 | D10: 0.05 | E10: 7.83 | F10: =C10*D10*E10 | G10: 0.5 | H10: 0.15 | I10: =F10*G10 | J10: =C10*(1-G10)*D10*H10*E10 | K10: =I10+J10 | L10: CLIENT DATA — (440+120+120)/month x 12 = 8,160/yr.
B11: Transaction Disputes | C11: 4800 | D11: 0.05 | E11: 7.83 | F11: =C11*D11*E11 | G11: 0.15 | H11: 0.2 | I11: =F11*G11 | J11: =C11*(1-G11)*D11*H11*E11 | K11: =I11+J11 | L11: CLIENT DATA — 400/month x 12 = 4,800/yr.
B12: Loan Servicing Inquiries | C12: 14040 | D12: 0.05 | E12: 7.83 | F12: =C12*D12*E12 | G12: 0.4 | H12: 0.2 | I12: =F12*G12 | J12: =C12*(1-G12)*D12*H12*E12 | K12: =I12+J12 | L12: CLIENT DATA — 1,170/month x 12 = 14,040/yr.
B13: Credit Card Info & Servicing | C13: 14400 | D13: 0.05 | E13: 7.83 | F13: =C13*D13*E13 | G13: 0.6 | H13: 0.2 | I13: =F13*G13 | J13: =C13*(1-G13)*D13*H13*E13 | K13: =I13+J13 | L13: CLIENT DATA — 1,200/month x 12 = 14,400/yr.
B14: Domestic Transfers (Call Center) | C14: 11280 | D14: 0.05 | E14: 7.83 | F14: =C14*D14*E14 | G14: 0.65 | H14: 0.15 | I14: =F14*G14 | J14: =C14*(1-G14)*D14*H14*E14 | K14: =I14+J14 | L14: CLIENT DATA — 940/month x 12 = 11,280/yr.
B15: Deposit & Other Product Enquiries | C15: 3480 | D15: 0.05 | E15: 7.83 | F15: =C15*D15*E15 | G15: 0.45 | H15: 0.15 | I15: =F15*G15 | J15: =C15*(1-G15)*D15*H15*E15 | K15: =I15+J15 | L15: CLIENT DATA — (150+140)/month x 12 = 3,480/yr.
B16: Call Center Subtotal | C16: =SUM(C9:C15) | F16: =SUM(F9:F15) | I16: =SUM(I9:I15) | J16: =SUM(J9:J15) | K16: =SUM(K9:K15)
B18: TOTAL SERVICING SAVINGS | F18: =SUM(F16) | I18: =I16 | J18: =J16 | K18: =K16
B21: GROWTH-ADJUSTED COST AVOIDANCE
B22: Projecting volume growth at 8%/year — staff NOT needed due to digital handling
B24: YoY Growth Rate | C24: 0.08
B25: Annual Hrs per FTE | C25: 1800
B26: Loaded Annual FTE Cost | C26: 55000
B27: Weighted Avg Time/Interaction (hrs) | C27: 0.084
B28: Weighted Avg Combined Impact | C28: 0.337
B30: Metric | C30: Y1 | D30: Y2 | E30: Y3 | F30: Y4 | G30: Y5
B31: Base Volume (current) | C31: =C16 | D31: =C31 | E31: =C31 | F31: =C31 | G31: =C31
B32: Growth Volume (incremental) | C32: =C31*((1+C24)^1-1) | D32: =C31*((1+C24)^2-1) | E32: =C31*((1+C24)^3-1) | F32: =C31*((1+C24)^4-1) | G32: =C31*((1+C24)^5-1)
B33: Handled Digitally | C33: =C32*C28 | D33: =D32*C28 | E33: =E32*C28 | F33: =F32*C28 | G33: =G32*C28
B34: FTEs Avoided | C34: =C33*C27/C25 | D34: =D33*C27/C25 | E34: =E33*C27/C25 | F34: =F33*C27/C25 | G34: =G33*C27/C25
B35: Evidence: E4, E5, E6 | C35: =C34*C26 | D35: =D34*C26 | E35: =E34*C26 | F35: =F34*C26 | G35: =G34*C26
B37: Branch Transactions
B38: Domestic Transfers (Branch) | C38: 1783836 | D38: 0.083 | E38: 7.83 | F38: =C38*D38*E38 | G38: 0.2 | H38: 0.15 | I38: =F38*G38 | J38: =C38*(1-G38)*D38*H38*E38 | K38: =I38+J38 | L38: CLIENT DATA — 148,653/month x 12 = 1,783,836/yr.
B39: International Transfers (Branch) | C39: 5544 | D39: 0.5 | E39: 7.83 | F39: =C39*D39*E39 | G39: 0.1 | H39: 0.15 | I39: =F39*G39 | J39: =C39*(1-G39)*D39*H39*E39 | K39: =I39+J39 | L39: CLIENT DATA — 462/month x 12 = 5,544/yr. TAT: 30 min branch.
B40: Bill Payments (Branch) | C40: 14976 | D40: 0.083 | E40: 7.83 | F40: =C40*D40*E40 | G40: 0.5 | H40: 0.2 | I40: =F40*G40 | J40: =C40*(1-G40)*D40*H40*E40 | K40: =I40+J40 | L40: CLIENT DATA — 1,248/month x 12 = 14,976/yr.
B41: Debit Card Ordering (Branch) | C41: 37512 | D41: 0.133 | E41: 7.83 | F41: =C41*D41*E41 | G41: 0.35 | H41: 0.2 | I41: =F41*G41 | J41: =C41*(1-G41)*D41*H41*E41 | K41: =I41+J41 | L41: CLIENT DATA — 3,126/month x 12 = 37,512/yr.
B42: Branch Transactions Subtotal | C42: =SUM(C38:C41) | F42: =SUM(F38:F41) | I42: =SUM(I38:I41) | J42: =SUM(J38:J41) | K42: =SUM(K38:K41)
B44: TOTAL SERVICING SAVINGS | F44: =SUM(F42) | I44: =I42 | J44: =J42 | K44: =K42
B47: GROWTH-ADJUSTED COST AVOIDANCE
B48: Projecting volume growth at 8%/year — staff NOT needed due to digital handling
B50: YoY Growth Rate | C50: 0.08
B51: Annual Hrs per FTE | C51: 1800
B52: Loaded Annual FTE Cost | C52: 55000
B53: Weighted Avg Time/Interaction (hrs) | C53: 0.084
...

Sheet Model Inputs
B2: Model Inputs
B3: Blue cells are editable. Change values and the model recalculates.
B5: Active Scenario | C5: =IF('Cashflows'!$C$5=1,"Conservative",IF('Cashflows'!$C$5=2,"Moderate","Aggressive")) | D5: (Change scenario on Cashflows sheet)
B7: BASIC INFORMATION
B8: Input | C8: Value | D8: Conf. | E8: Assumption/Comment | F8: Source
B9: Total Customers | C9: 3656262 | D9: LOW | E9: CLIENT DATA — Data Request: 3,656,262 retail customers.
B10: Annual Revenue | C10: 145796000 | D10: LOW | E10: DERIVED — 3,656,262 x $39.87 TOI/customer = $145.8M retail income.
B11: Cost To Income Ratio | C11: 0.3328 | D11: LOW
B12: Operating Costs | C12: 48500000 | D12: LOW | E12: ESTIMATED — Retail share of bank-wide OpEx. REQUIRES VALIDATION.
B13: Total Fte | C13: 5265 | D13: LOW | E13: CLIENT DATA — 5,265 total FTE (3,136 branch + 2,129 back-office).
B14: Average Fte Rate Hour | C14: 7.83 | D14: LOW
B15: Average Revenue Per Customer | C15: 39.87 | D15: LOW | E15: CLIENT DATA — TOI/customer/year (2024).
B17: FINANCIAL PARAMETERS
B18: Discount Rate (WACC) | C18: 0.1
B19: Analysis Period (Years) | C19: 5
B20: YoY Growth Rate | C20: 0.08
B22: LEVER GROUP INPUTS
B23: L1: Digital Onboarding Funnel Recovery
B24: Digital Onboarding Funnel Recovery
B25: Annual Downloads | C25: 513447 | D25: HIGH | E25: Annual digital onboarding application starts | F25: CLIENT DATA — App downloads (3-year average). Android: 153K, iOS: 361K.
B26: Current Drop Rate | C26: 0.4 | D26: HIGH | E26: Drop-off rate before registration | F26: CLIENT DATA — 40% drop between download and registration (513K to 307K).
B27: Completion Rate | C27: 0.83 | D27: HIGH | E27: Registration-to-completion rate | F27: CLIENT DATA — Q4 2024: 43,191 complete / 52,075 register = 82.9%.
B28: Net Incremental Factor | C28: 0.6 | D28: LOW | E28: Net incrementality of recovered customers | F28: ESTIMATE — 60% of recovered customers are truly incremental (rest would have gone to branch).
B29: Revenue Per Customer | C29: 39.87 | D29: HIGH | E29: Annual revenue per customer | F29: CLIENT DATA — TOI/customer/year.
B30: Backbase Impact | C30: =INDEX('Scenario Data'!$C$24:$E$24,1,'Cashflows'!$C$5) | D30: MEDIUM | E30: Percentage of drop-off volume recovered by Backbase Digital Onboarding | F30: GAP-BASED — Client leakage: 80%. BIC: 50%. Gap: 30pp. Capture Rate: 0.40. Impact: 30pp x 0.40 = 12pp.
B31: Baseline Annual | C31: =C25 * C26 * C27 * C28 * C29
B32: Annual Benefit (Steady State) | C32: =C31*C30
B34: Branch-to-Digital Onboarding Migration
B35: Annual Branch Openings | C35: 193177 | D35: HIGH | E35: Annual branch account openings | F35: CLIENT DATA — 193,177 branch account openings per year.
B36: Time Saved Hours | C36: 0.133 | D36: HIGH | E36: Time saved per shifted account (8 min) | F36: CLIENT DATA — Branch: 10 min, Digital: 2 min. Saved: 8 min = 0.133 hrs per account.
B37: Fte Rate | C37: 7.83 | D37: LOW | E37: Blended FTE hourly rate | F37: DERIVED — Est. staff costs $82.5M / 5,265 FTE / 2,000 hrs = $7.83/hr.
B38: Backbase Impact | C38: 0.25 | D38: MEDIUM | E38: Percentage of branch openings shifted to digital | F38: BACKBASE BENCHMARK — 20-30% branch-to-digital shift typical in first 2 years of digital onboarding.
B39: Baseline Annual | C39: =C35 * C36 * C37
B40: Annual Benefit (Steady State) | C40: =C39*C38
B43: L2: Onboarding Cycle Time Acceleration
B44: Onboarding Processing Cost Reduction via STP
B45: Annual Applications | C45: 448000 | D45: MEDIUM | E45: Total annual onboarding application volume | F45: DERIVED — 255K digital + 193K branch = ~448K total new accounts per year.
B46: Manual Processing Hours | C46: 0.25 | D46: LOW | E46: Average back-office processing time per application | F46: ESTIMATE — 15 min average back-office processing per application (KYC check + account activation + compliance).
B47: Fte Rate | C47: 7.83 | D47: LOW | E47: Blended FTE hourly rate | F47: DERIVED — Est. staff costs / FTE / 2,000 hrs.
B48: Backbase Impact | C48: =INDEX('Scenario Data'!$C$25:$E$25,1,'Cashflows'!$C$5) | D48: MEDIUM | E48: STP improvement as fraction of current manual processing volume | F48: GAP-BASED — Client STP: 45%. BIC: 85%. Gap: 40pp. Capture Rate: 0.40. Impact: 40pp x 0.40 = 16pp.
...

Sheet Scenario Data
B2: Scenario Definitions
B3: Edit values here to customize scenarios. All lever sheets reference this table.
B5: Parameter | C5: Conservative | D5: Moderate | E5: Aggressive
B7: IMPLEMENTATION CURVES
B8: Default
B9: Year 1 | C9: 0.2 | D9: 0.3 | E9: 0.4
B10: Year 2 | C10: 0.55 | D10: 0.7 | E10: 0.8
B11: Year 3 | C11: 0.75 | D11: 0.8 | E11: 0.9
B12: Year 4 | C12: 0.9 | D12: 1 | E12: 1
B13: Year 5 | C13: 1 | D13: 1 | E13: 1
B15: EFFECTIVENESS CURVES
B16: Default
B17: Year 1 | C17: 0.1 | D17: 0.15 | E17: 0.2
B18: Year 2 | C18: 0.25 | D18: 0.35 | E18: 0.45
B19: Year 3 | C19: 0.45 | D19: 0.6 | E19: 0.7
B20: Year 4 | C20: 0.7 | D20: 0.85 | E20: 0.9
B21: Year 5 | C21: 0.9 | D21: 1 | E21: 1
B23: BACKBASE IMPACTS
B24: L1 Funnel Recovery | C24: 0.09 | D24: 0.12 | E24: 0.15
B25: L2 Cycle Time Acceleration | C25: 0.12 | D25: 0.16 | E25: 0.2
B26: L3 Call Center Deflection | C26: 0.12 | D26: 0.16 | E26: 0.2
B27: L4 Branch Digital Migration | C27: 0.14 | D27: 0.19 | E27: 0.24
B28: L5 Digital Adoption | C28: 0.1 | D28: 0.14 | E28: 0.18
B29: L6 Backoffice Stp | C29: 0.14 | D29: 0.18 | E29: 0.22
B30: L7 Digital Lending | C30: 0.06 | D30: 0.08 | E30: 0.1

Sheet Bank Profile
B1: Bank Profile
B3: BANK IDENTITY
B4: Bank Name | C4: SeABank — Retail Banking Division
B5: Country
B6: Currency | C6: USD
B7: Stock Ticker | C7: N/A
B8: Report Year
B9: Data Sources
B11: Market Context Status | C11: NOT_RUN
B13: KEY FINANCIAL METRICS
B14: Metric | C14: Value | D14: Confidence | E14: Source
B15: Total Customers | C15: 3656262 | D15: HIGH | E15: Client Data / Questionnaire
B16: Annual Revenue | C16: 145796000 | D16: HIGH | E16: Client Data / Questionnaire
B17: Operating Costs | C17: 48500000 | D17: MEDIUM | E17: Client Data / Questionnaire
B18: Total FTE | C18: 5265 | D18: MEDIUM | E18: Client Data / Questionnaire
B20: ADDITIONAL CONTEXT (Annual Report / Market Research)
B21: Metric | C21: Value | D21: Confidence | E21: Source
B22: Total Assets | C22: $12.85B (VND 325,699B, +22% YoY FY2024) | D22: HIGH | E22: SeABank FY2024 Annual Report
B23: Total Loans | C23: $8.26B (VND 209,355B, +20.4% YoY FY2024) | D23: HIGH | E23: SeABank FY2024 Annual Report
B24: Total Deposits | C24: $8.52B (VND 215,984B, +23% YoY FY2024) | D24: HIGH | E24: SeABank FY2024 Annual Report
B25: Num Branches | C25: 180 | D25: HIGH | E25: SeABank FY2024 Annual Report
B26: Npl Ratio | C26: 1.89% | D26: HIGH | E26: SeABank FY2024 Annual Report
B27: Roe | C27: 14.75% | D27: HIGH | E27: SeABank FY2024 Annual Report
B28: Roa | C28: 1.63% | D28: HIGH | E28: SeABank FY2024 Annual Report
B29: Digital Transactions | C29: 52.6M (+160% YoY FY2024) | D29: HIGH | E29: SeABank FY2024 Annual Report
B30: Casa Ratio | C30: 19.4% | D30: HIGH | E30: SeABank FY2024 Annual Report
B31: Digital Enrollment | C31: 82% | D31: HIGH | E31: SeABank FY2024 Annual Report
B32: Digital Active Rate | C32: 12% (1 tx/month definition) | D32: HIGH | E32: SeABank FY2024 Annual Report
B33: Customer Churn | C33: 2% annual | D33: HIGH | E33: SeABank FY2024 Annual Report
B34: Product Penetration | C34: 2.53 (target: 4) | D34: HIGH | E34: SeABank FY2024 Annual Report
B35: Customer Growth Yoy | C35: 21.6% 3-year average | D35: HIGH | E35: SeABank FY2024 Annual Report
B36: Core Banking | C36: Temenos T24 R22 + Way4 card management | D36: HIGH | E36: SeABank FY2024 Annual Report
B37: Segments | C37: Mass: 3,467,741 (94.8%) | Mass Affluent: 150,028 (4.1%) | Affluent: 38,493 (1.05%) | D37: HIGH | E37: SeABank FY2024 Annual Report
B39: DATA GAPS
B40: Data Needed | C40: Priority | D40: Impact | E40: Where to Obtain
C41: CRITICAL | D41: Required to validate FTE hourly rate ($7.83) used in all servicing calculations | E41: HR/Finance — returned N/A in data request
C42: CRITICAL | D42: Needed to size call center deflection savings independently | E42: Head of Contact Center
C43: HIGH | D43: Validates STP improvement and digital lending shift assumptions | E43: Head of Retail Lending
C44: HIGH | D44: Validates $150/loan revenue assumption driving $2.6M CLO benefit | E44: Finance / Lending Analytics
C45: MEDIUM | D45: Would enable acquisition efficiency driver (not currently modeled) | E45: Marketing/Finance

Sheet Assumptions
B1: Assumptions Register
B3: All assumptions documented with sources and validation owners
B5: ID | C5: Assumption | D5: Value | E5: Conf. | F5: Source | G5: Owner | H5: Sensitivity
B6: SB-A1 | C6: Total Retail Customers | D6: 3,656,262 | E6: HIGH | F6: CLIENT DATA — Data request confirmed. | G6: Head of Retail | H6: HIGH — Affects all per-customer calculations
B7: SB-A2 | C7: Revenue per Customer (TOI) | D7: $39.87/year | E7: HIGH | F7: CLIENT DATA — TOI/customer/year (2024). | G7: Finance | H7: HIGH — Core revenue metric
B8: SB-A3 | C8: Digital Active Rate | D8: 12% (1 tx/month) | E8: HIGH | F8: CLIENT DATA — Definition: 1 transaction per month. | G8: Digital Banking | H8: HIGH — Determines addressable base for CLO and digital cross-sell
B9: SB-A4 | C9: Product Penetration | D9: 2.53 (target: 4) | E9: HIGH | F9: CLIENT DATA — Product holding per active customer. | G9: Head of Retail Products | H9: HIGH — Drives loyalty & cross-sell revenue
B10: SB-A5 | C10: Customer Churn Rate | D10: 2% annual | E10: HIGH | F10: CLIENT DATA. | G10: Finance | H10: MEDIUM — Drives retention benefit
B11: SB-A6 | C11: FTE Hourly Rate | D11: $7.83/hour | E11: LOW | F11: DERIVED — Est. staff costs / FTE / 2,000 hrs. Cost per FTE returned N/A in data request. | G11: HR/Finance | H11: HIGH — Multiplied across all servicing calculations
B12: SB-A7 | C12: Digital Leakage Rate (Current) | D12: 80% digital onboarding leakage | E12: MEDIUM | F12: DERIVED — 513K downloads, 307K register (60%), ~255K complete (~50%). Leakage from start to complete ~80%. Aligns with Average benchmark (70-90%). | G12: Digital Banking | H12: HIGH — Drives L1 funnel recovery sizing
B13: SB-A8 | C13: Current STP Rate | D13: ~45% (<50%) | E13: MEDIUM | F13: INFERRED — Evidence: 'teams still rely on manual workarounds' (E8). Poor range is <50%. | G13: COD / Operations | H13: HIGH — Drives L2 and L6 sizing
B14: SB-A9 | C14: CLO Acceptance Rate | D14: 4% of digitally active base | E14: MEDIUM | F14: BACKBASE BENCHMARK — SE Asian retail CLO: 3-6%. | G14: Value Consulting / Lending | H14: HIGH — Primary driver of lending revenue
B15: SB-A10 | C15: Revenue per New Loan Product | D15: $150/year | E15: LOW | F15: ESTIMATE — NIM on avg $2K unsecured loan at ~7.5% margin. | G15: Head of Retail Lending / Finance | H15: HIGH — Directly impacts lending journey benefit
B16: SB-A11 | C16: VND/USD Exchange Rate | D16: VND 25,000 = $1 USD | E16: MEDIUM | F16: MARKET — Approximate mid-2024 rate. | G16: Treasury | H16: HIGH — All VND values converted at this rate
... B19: SB-A14 | C19: Backbase Investment (License + Implementation) | D19: $11M over 5 years ($7M license + $4M implementation) | E19: LOW | F19: ESTIMATE — Requires commercial validation with Backbase pricing team. | G19: Backbase Commercial | H19: HIGH — Determines ROI, NPV, and payback

Sheet Data Gaps
B1: Data Gaps — Required for Validation
B3: These data points are CRITICAL for validating the ROI model.
B5: ID | C5: Data Needed | D5: Priority | E5: Source | F5: Impact on Model
B6: SB-DG1 | C6: Average Cost per FTE — blended across branch and back-office | D6: CRITICAL | E6: HR/Finance — returned N/A in data request | F6: Validates FTE hourly rate ($7.83) used in all servicing and efficiency calculations
B7: SB-DG2 | C7: Call Center FTE count and cost structure | D7: CRITICAL | E7: Head of Contact Center — not provided in data request | F7: Validates call center deflection savings and sizes staffing benefit
B8: SB-DG3 | C8: USL application funnel by channel (starts, completed, approved) | D8: HIGH | E8: Head of Retail Lending — multiple fields returned N/A | F8: Validates STP improvement rate and digital lending shift assumptions
B9: SB-DG4 | C9: Average loan size and revenue per unsecured loan product | D9: HIGH | E9: Finance / Lending Analytics | F9: Validates $150/loan revenue assumption driving CLO benefit
B10: SB-DG5 | C10: Customer Acquisition Cost by channel (digital vs branch vs partner) | D10: HIGH | E10: Marketing/Finance — returned N/A in data request | F10: Would enable acquisition efficiency driver (not currently modeled)
B11: SB-DG6 | C11: Current STP rate — actual measurement | D11: HIGH | E11: COD / Operations — process analytics | F11: Currently inferred as <50% from evidence. Actual rate would validate L2 and L6 gap calculations.
B12: SB-DG7 | C12: Digital onboarding funnel with exact step-level drop-off reasons | D12: MEDIUM | E12: Digital Banking — Insider database logs | F12: Validates funnel recovery assumptions and sizes onboarding revenue benefit
B13: SB-DG8 | C13: Segment-level P&L (Mass vs Affluent vs Priority) | D13: MEDIUM | E13: Finance — segment economics | F13: Would enable segment-specific ROI and validate 'Affluent = 80% revenue' assertion
