Workbook
Name ScenarioIndex: 'Cashflows'!$C$5
Name DiscountRate: 'Model Inputs'!$C11
Name License_Y1: 'Model Inputs'!$C144
Name Impl_Y1: 'Model Inputs'!$C151
Name License_Y2: 'Model Inputs'!$C145
Name Impl_Y2: 'Model Inputs'!$C152
Name License_Y3: 'Model Inputs'!$C146
Name Impl_Y3: 'Model Inputs'!$C153
Name License_Y4: 'Model Inputs'!$C147
Name Impl_Y4: 'Model Inputs'!$C154
Name License_Y5: 'Model Inputs'!$C148
Name Impl_Y5: 'Model Inputs'!$C155

Sheet Cover Page
B5: Return on Investment Calculator
B7: Value Consulting - Business Case
B10: Client Name: | C10: Navy Federal Investment Services (NFIS)
B12: Date: | C12: 2026-04-08
B14: Currency: | C14: USD
B16: Analysis Period: | C16: 5 Years
B18: Selected Scenario: | C18: moderate
B20: Discount Rate: | C20: 10.0%
B24: DATA SOURCE LEGEND
B26: Green | C26: From transcript/client data
B27: Yellow | C27: Estimate - requires validation
B28: Blue | C28: Backbase benchmark
B29: Red border | C29: Low confidence - critical validation

Sheet Instructions
B2: ROI Model Instructions
B5: THIS IS A LIVE MODEL — all calculations use Excel formulas.
B6: Changing any input on 'Model Inputs' will automatically recalculate all sheets.
B8: SCENARIO SWITCHING
B9: • Go to 'Model Inputs' sheet, cell C5
B10: • Select: 1 = Conservative, 2 = Moderate, 3 = Aggressive
B11: • All curves, impacts, and downstream calculations will update instantly
B13: EDITING INPUTS
B14: • Blue-shaded cells on 'Model Inputs' are editable — change volumes, rates, costs
B15: • Yellow cells are estimates that should be validated with client data
B16: • Green cells are from transcript — highest confidence
B18: SHEET ARCHITECTURE
... B28: • LOW - Estimate based on typical patterns - REQUIRES VALIDATION

Sheet Table of Contents
B3: Table of Contents
B5: Input Layer | C5: Model Inputs — editable parameters
C6: Scenario Data — Conservative / Moderate / Aggressive
B7: Calculation | C7: Servicing Detail — task-level breakdown
C8: Lever: Banking-to-DI Cross-Sell Activation
C9: Lever: Onboarding-to-Funding Funnel Recovery
C10: Lever: AUM Growth via Digital Engagement
C11: Lever: DI-to-FA Tier Upgrade — Automated Threshold Routing
C12: Lever: ACAT / Asset Consolidation
C13: Lever: Self-Directed to Managed/Robo Conversion
C14: Lever: Retention & Asset Outflow Prevention
C15: Lever: Servicing Cost Reduction — Chat/Email Deflection + Process Automation
C16: Lever: Advisor Referral Pipeline Acceleration
C17: Lever: Member Onboarding Cost Reduction
C18: Cashflows — 5-year projection
B19: Output Layer | C19: Results Dashboard — NPV, IRR, Payback, ROI
B20: Reference | C20: Assumptions Register
C21: Data Gaps for Validation

Sheet Cashflows
B1: 5 Year Cashflows & ROI
B3: All values are live formulas. Change the scenario below — Journey Analysis and Cashflows update automatically.
B4: SCENARIO SELECTOR
B5: Active Scenario (1=Conservative, 2=Moderate, 3=Aggressive) | C5: 2
B6: =IF(C5=1,"Conservative — slower adoption, cautious assumptions",IF(C5=2,"Moderate — base case, phased rollout","Aggressive — fast adoption, full benefit"))
C8: Year 1 | D8: Year 2 | E8: Year 3 | F8: Year 4 | G8: Year 5 | H8: Total
B9: CASH INFLOWS (Benefits)
B10: Banking-to-DI Cross-Sell Activation | C10: ='Journey Analysis'!C17*'Model Inputs'!C161*'Model Inputs'!C167 | D10: ='Journey Analysis'!C17*'Model Inputs'!C162*'Model Inputs'!C168 | E10: ='Journey Analysis'!C17*'Model Inputs'!C163*'Model Inputs'!C169 | F10: ='Journey Analysis'!C17*'Model Inputs'!C164*'Model Inputs'!C170 | G10: ='Journey Analysis'!C17*'Model Inputs'!C165*'Model Inputs'!C171 | H10: =SUM(C10:G10)
B11: Onboarding-to-Funding Funnel Recovery | C11: ='Journey Analysis'!C32*'Model Inputs'!C161*'Model Inputs'!C167 | D11: ='Journey Analysis'!C32*'Model Inputs'!C162*'Model Inputs'!C168 | E11: ='Journey Analysis'!C32*'Model Inputs'!C163*'Model Inputs'!C169 | F11: ='Journey Analysis'!C32*'Model Inputs'!C164*'Model Inputs'!C170 | G11: ='Journey Analysis'!C32*'Model Inputs'!C165*'Model Inputs'!C171 | H11: =SUM(C11:G11)
B12: AUM Growth via Digital Engagement | C12: ='Journey Analysis'!C47*'Model Inputs'!C161*'Model Inputs'!C167 | D12: ='Journey Analysis'!C47*'Model Inputs'!C162*'Model Inputs'!C168 | E12: ='Journey Analysis'!C47*'Model Inputs'!C163*'Model Inputs'!C169 | F12: ='Journey Analysis'!C47*'Model Inputs'!C164*'Model Inputs'!C170 | G12: ='Journey Analysis'!C47*'Model Inputs'!C165*'Model Inputs'!C171 | H12: =SUM(C12:G12)
B13: DI-to-FA Tier Upgrade — Automated Threshold Routing | C13: ='Journey Analysis'!C62*'Model Inputs'!C161*'Model Inputs'!C167 | D13: ='Journey Analysis'!C62*'Model Inputs'!C162*'Model Inputs'!C168 | E13: ='Journey Analysis'!C62*'Model Inputs'!C163*'Model Inputs'!C169 | F13: ='Journey Analysis'!C62*'Model Inputs'!C164*'Model Inputs'!C170 | G13: ='Journey Analysis'!C62*'Model Inputs'!C165*'Model Inputs'!C171 | H13: =SUM(C13:G13)
B14: ACAT / Asset Consolidation | C14: ='Journey Analysis'!C77*'Model Inputs'!C161*'Model Inputs'!C167 | D14: ='Journey Analysis'!C77*'Model Inputs'!C162*'Model Inputs'!C168 | E14: ='Journey Analysis'!C77*'Model Inputs'!C163*'Model Inputs'!C169 | F14: ='Journey Analysis'!C77*'Model Inputs'!C164*'Model Inputs'!C170 | G14: ='Journey Analysis'!C77*'Model Inputs'!C165*'Model Inputs'!C171 | H14: =SUM(C14:G14)
B15: Self-Directed to Managed/Robo Conversion | C15: ='Journey Analysis'!C91*'Model Inputs'!C161*'Model Inputs'!C167 | D15: ='Journey Analysis'!C91*'Model Inputs'!C162*'Model Inputs'!C168 | E15: ='Journey Analysis'!C91*'Model Inputs'!C163*'Model Inputs'!C169 | F15: ='Journey Analysis'!C91*'Model Inputs'!C164*'Model Inputs'!C170 | G15: ='Journey Analysis'!C91*'Model Inputs'!C165*'Model Inputs'!C171 | H15: =SUM(C15:G15)
B16: Retention & Asset Outflow Prevention | C16: ='Journey Analysis'!C106*'Model Inputs'!C161*'Model Inputs'!C167 | D16: ='Journey Analysis'!C106*'Model Inputs'!C162*'Model Inputs'!C168 | E16: ='Journey Analysis'!C106*'Model Inputs'!C163*'Model Inputs'!C169 | F16: ='Journey Analysis'!C106*'Model Inputs'!C164*'Model Inputs'!C170 | G16: ='Journey Analysis'!C106*'Model Inputs'!C165*'Model Inputs'!C171 | H16: =SUM(C16:G16)
B17: Servicing Cost Reduction — Chat/Email Deflection + Process Automation | C17: ='Journey Analysis'!C152*'Model Inputs'!C161*'Model Inputs'!C167 | D17: ='Journey Analysis'!C152*'Model Inputs'!C162*'Model Inputs'!C168 | E17: ='Journey Analysis'!C152*'Model Inputs'!C163*'Model Inputs'!C169 | F17: ='Journey Analysis'!C152*'Model Inputs'!C164*'Model Inputs'!C170 | G17: ='Journey Analysis'!C152*'Model Inputs'!C165*'Model Inputs'!C171 | H17: =SUM(C17:G17)
B18: Advisor Referral Pipeline Acceleration | C18: ='Journey Analysis'!C165*'Model Inputs'!C161*'Model Inputs'!C167 | D18: ='Journey Analysis'!C165*'Model Inputs'!C162*'Model Inputs'!C168 | E18: ='Journey Analysis'!C165*'Model Inputs'!C163*'Model Inputs'!C169 | F18: ='Journey Analysis'!C165*'Model Inputs'!C164*'Model Inputs'!C170 | G18: ='Journey Analysis'!C165*'Model Inputs'!C165*'Model Inputs'!C171 | H18: =SUM(C18:G18)
B19: Member Onboarding Cost Reduction | C19: ='Journey Analysis'!C179*'Model Inputs'!C161*'Model Inputs'!C167 | D19: ='Journey Analysis'!C179*'Model Inputs'!C162*'Model Inputs'!C168 | E19: ='Journey Analysis'!C179*'Model Inputs'!C163*'Model Inputs'!C169 | F19: ='Journey Analysis'!C179*'Model Inputs'!C164*'Model Inputs'!C170 | G19: ='Journey Analysis'!C179*'Model Inputs'!C165*'Model Inputs'!C171 | H19: =SUM(C19:G19)
B21: Total Cash Inflow | C21: =SUM(C10:C19) | D21: =SUM(D10:D19) | E21: =SUM(E10:E19) | F21: =SUM(F10:F19) | G21: =SUM(G10:G19) | H21: =SUM(H10:H19)
B24: CASH OUTFLOWS (Investment)
B25: License | C25: ='Model Inputs'!C144 | D25: ='Model Inputs'!C145 | E25: ='Model Inputs'!C146 | F25: ='Model Inputs'!C147 | G25: ='Model Inputs'!C148 | H25: =SUM(C25:G25)
B26: Implementation | C26: ='Model Inputs'!C151 | D26: ='Model Inputs'!C152 | E26: ='Model Inputs'!C153 | F26: ='Model Inputs'!C154 | G26: ='Model Inputs'!C155 | H26: =SUM(C26:G26)
B27: Total Cash Outflow | C27: =C25+C26 | D27: =D25+D26 | E27: =E25+E26 | F27: =F25+F26 | G27: =G25+G26 | H27: =H25+H26
B30: NET CASHFLOW | C30: =C21-C27 | D30: =D21-D27 | E30: =E21-E27 | F30: =F21-F27 | G30: =G21-G27 | H30: =SUM(C30:G30)
B31: Cumulative Cashflow | C31: =C30 | D31: =C31+D30 | E31: =D31+E30 | F31: =E31+F30 | G31: =F31+G30
B35: FINANCIAL METRICS
B36: Discount Rate (WACC) | C36: ='Model Inputs'!C11
B37: Total 5-Year Benefits | C37: =H21
B38: Total 5-Year Investment | C38: =H27
B39: Net Benefit | C39: =C37-C38
B40: ROI % | C40: =IFERROR((C37-C38)/C38,0)
B41: Net Present Value (NPV) | C41: =NPV(C36,C30:G30)
B42: Internal Rate of Return (IRR) | C42: =IFERROR(IRR(C30:G30),"N/A")
B43: Payback Period (Years) | C43: =IF(C31>=0,1-((C31-C30)/C30),IF(D31>=0,2-((D31-D30)/D30),IF(E31>=0,3-((E31-E30)/E30),IF(F31>=0,4-((F31-F30)/F30),IF(G31>=0,5-((G31-G30)/G30),"N/A")))))
B47: BENEFITS BY LEVER (Annual Steady State)
B49: Lever Group | C49: Lifecycle Stage | D49: Annual Benefit
B50: Banking-to-DI Cross-Sell Activation | D50: ='Journey Analysis'!C17
B51: Onboarding-to-Funding Funnel Recovery | D51: ='Journey Analysis'!C32
B52: AUM Growth via Digital Engagement | D52: ='Journey Analysis'!C47
B53: DI-to-FA Tier Upgrade — Automated Threshold Routing | D53: ='Journey Analysis'!C62
B54: ACAT / Asset Consolidation | D54: ='Journey Analysis'!C77
...

Sheet Journey Analysis
B1: Journey Analysis — Benefit Calculation Chain
B2: Active Scenario: | C2: =IF('Cashflows'!$C$5=1,"Conservative",IF('Cashflows'!$C$5=2,"Moderate","Aggressive")) | D2: (Change on Cashflows sheet)
B3: Each lever: input factors → Baseline (formula) → × Backbase Impact → Annual Benefit. Change scenario on Cashflows to update scenario-linked impacts.
B5: Banking-to-DI Cross-Sell Activation
B6: Revenue Generation
B7: Incremental Fee Revenue from Banking-to-DI Cross-Sell | D7: Revenue
B8: Factor | C8: Value | D8: Unit
B9: Eligible Members | C9: ='Model Inputs'!C18 | D9: members
B10: Penetration Gap | C10: ='Model Inputs'!C19 | D10: ratio
B11: Blended Revenue Per Member | C11: ='Model Inputs'!C20 | D11: USD/yr
B12: Baseline | C12: =C9 * C10 * C11 | D12: USD/year
B13: Backbase Impact | C13: ='Model Inputs'!C21 | D13: % of baseline captured by Backbase
B14: Annual Benefit | C14: =C12*C13 | D14: USD/year (scenario-adjusted)
B17: Total: Banking-to-DI Cross-Sell Activation | C17: =C14
B20: Onboarding-to-Funding Funnel Recovery
B21: Revenue Generation
B22: Recovered Fee Revenue from Unfunded Account Activation | D22: Revenue
B23: Factor | C23: Value | D23: Unit
B24: Annual New Accounts | C24: ='Model Inputs'!C28 | D24: accounts/yr
B25: Unfunded Rate | C25: ='Model Inputs'!C29 | D25: ratio
B26: Blended Revenue Per Funded | C26: ='Model Inputs'!C30 | D26: USD/yr
B27: Baseline | C27: =C24 * C25 * C26 | D27: USD/year
B28: Backbase Impact | C28: ='Model Inputs'!C31 | D28: % of baseline captured by Backbase
B29: Annual Benefit | C29: =C27*C28 | D29: USD/year (scenario-adjusted)
B32: Total: Onboarding-to-Funding Funnel Recovery | C32: =C29
B35: AUM Growth via Digital Engagement
B36: Revenue Generation
B37: Incremental Fee Revenue from AUM Uplift on Engaged Robo Members | D37: Revenue
B38: Factor | C38: Value | D38: Unit
B39: Robo Members | C39: ='Model Inputs'!C38 | D39: members
B40: Avg Aum | C40: ='Model Inputs'!C39 | D40: USD
B41: Fee Rate | C41: ='Model Inputs'!C40 | D41: ratio
B42: Baseline | C42: =C39 * C40 * C41 | D42: USD/year
B43: Backbase Impact | C43: ='Model Inputs'!C41 | D43: % of baseline captured by Backbase
B44: Annual Benefit | C44: =C42*C43 | D44: USD/year (scenario-adjusted)
B47: Total: AUM Growth via Digital Engagement | C47: =C44
B50: DI-to-FA Tier Upgrade — Automated Threshold Routing
B51: Revenue Generation
B52: Incremental Fee Revenue from DI-to-FA Conversions | D52: Revenue
B53: Factor | C53: Value | D53: Unit
...

Sheet Servicing Detail
B1: Customer Servicing — Channel Analysis
B3: Vol Saving = Baseline × Vol Deflection. Time Saving = Remaining Vol × Time × Time Reduction × Rate. Total = Vol + Time Saving.
B5: Task | C5: Volume | D5: Time (hrs) | E5: Rate | F5: Baseline | G5: Vol Deflection | H5: Time Reduction | I5: Vol Saving | J5: Time Saving | K5: Total Saved | L5: Source
B6: Evidence:

Sheet Model Inputs
B2: Model Inputs
B3: Blue cells are editable. Change values and the model recalculates.
B5: Active Scenario | C5: =IF('Cashflows'!$C$5=1,"Conservative",IF('Cashflows'!$C$5=2,"Moderate","Aggressive")) | D5: (Change scenario on Cashflows sheet)
B7: BASIC INFORMATION
B8: Input | C8: Value | D8: Conf. | E8: Assumption/Comment | F8: Source
B10: FINANCIAL PARAMETERS
B11: Discount Rate (WACC) | C11: 0.1
B12: Analysis Period (Years) | C12: 5
B13: YoY Growth Rate | C13: 0
B15: LEVER GROUP INPUTS
B16: Banking-to-DI Cross-Sell Activation
B17: Incremental Fee Revenue from Banking-to-DI Cross-Sell
B18: Eligible Members | C18: 14000000 | D18: HIGH | F18: NFCU total membership (E1)
B19: Penetration Gap | C19: 0.022 | D19: MEDIUM | F19: Gap: 3% CU benchmark - 0.8% current (E8, E9)
B20: Blended Revenue Per Member | C20: 32.33 | D20: MEDIUM | F20: Derived: (0.667 × $10K × 0.275%) + (0.333 × $42)
B21: Backbase Impact | C21: 0.4 | D21: MEDIUM | F21: Gap capture rate: 40% of 2.2pp gap. P3 — standard capture rate for cross-sell with NBA engine (Digital Engage). No direct P1 investing cross-sell data in playbook; roi_levers.md Lever 1 establishes framework.
B22: Baseline Annual | C22: =C18 * C19 * C20
B23: Annual Benefit (Steady State) | C23: =C22*C21
B26: Onboarding-to-Funding Funnel Recovery
B27: Recovered Fee Revenue from Unfunded Account Activation
B28: Annual New Accounts | C28: 40000 | D28: MEDIUM | F28: Estimated: 115K-to-800K growth trajectory, conservative at 40K/yr vs 137K required (E1)
B29: Unfunded Rate | C29: 0.5 | D29: HIGH | F29: 50% of closed accounts never funded (E5, E21)
B30: Blended Revenue Per Funded | C30: 23.16 | D30: MEDIUM | F30: Derived: (0.667 × $5K × 0.275%) + (0.333 × $42)
B31: Backbase Impact | C31: 0.38 | D31: HIGH | F31: P1 — Consulting Playbook: Eastern Bank (USA, Vendor: Backbase) achieved 69% funded rate vs NFIS 50%. Improvement: 19pp. Capture of unfunded pool: 19/50 = 38%. Comparable because: US bank, Backbase Digital Onboarding with Account Funding journey.
B32: Baseline Annual | C32: =C28 * C29 * C30
B33: Annual Benefit (Steady State) | C33: =C32*C31
B36: AUM Growth via Digital Engagement
B37: Incremental Fee Revenue from AUM Uplift on Engaged Robo Members
B38: Robo Members | C38: 76705 | D38: MEDIUM | F38: Derived: 115K × 0.667 robo mix (E6)
B39: Avg Aum | C39: 4350 | D39: MEDIUM | F39: Derived: $500M / 115K members (E3)
B40: Fee Rate | C40: 0.00275 | D40: MEDIUM | F40: Robo advisory fee rate ~0.275%
B41: Backbase Impact | C41: 0.15 | D41: MEDIUM | F41: P2 — McKinsey wealth engagement research: engaged digital investors show 15-20% AUM uplift vs non-engaged. Using 15% (base estimate). Capability: Digital Engage behavioral triggers, Digital Invest goal tracking, surplus cash alerts.
B42: Baseline Annual | C42: =C38 * C39 * C40
B43: Annual Benefit (Steady State) | C43: =C42*C41
B46: DI-to-FA Tier Upgrade — Automated Threshold Routing
B47: Incremental Fee Revenue from DI-to-FA Conversions
B48: Eligible Members | C48: 8050 | D48: LOW | F48: Estimated: 7% of 115K DI members above FA threshold ($50K+). Grows as DI base expands.
B49: Avg Aum Eligible | C49: 75000 | D49: LOW | F49: Estimated avg AUM for threshold-eligible members
B50: Fee Delta | C50: 0.00375 | D50: LOW | F50: FA fee (0.65%) minus Robo fee (0.275%) = 37.5 bps delta
B51: Backbase Impact | C51: 0.3 | D51: LOW | F51: P3 — Consultant assumption. No P1 playbook data for automated tier-routing in investing. No P2 published research found for 'automated AUM threshold advisor routing conversion rate'. Reasoning: 30% capture is conservative for automated detection + streamlined upgrade — members already demonstrated investing behavior. Capability: Digital Invest AUM monitoring + Digital Assist advisor notification.
...

Sheet Scenario Data
B2: Scenario Definitions
B3: Edit values here to customize scenarios. All lever sheets reference this table.
B5: Parameter | C5: Conservative | D5: Moderate | E5: Aggressive
B7: IMPLEMENTATION CURVES
B8: Default
B9: Year 1 | C9: 0.25 | D9: 0.3 | E9: 0.35
B10: Year 2 | C10: 0.65 | D10: 0.75 | E10: 0.8
B11: Year 3 | C11: 1 | D11: 1 | E11: 1
B12: Year 4 | C12: 1 | D12: 1 | E12: 1
B13: Year 5 | C13: 1 | D13: 1 | E13: 1
B15: EFFECTIVENESS CURVES
B16: Default
B17: Year 1 | C17: 0.2 | D17: 0.25 | E17: 0.3
B18: Year 2 | C18: 0.4 | D18: 0.5 | E18: 0.55
B19: Year 3 | C19: 0.6 | D19: 0.7 | E19: 0.8
B20: Year 4 | C20: 0.75 | D20: 0.85 | E20: 0.9
B21: Year 5 | C21: 0.85 | D21: 0.95 | E21: 0.95
B23: BACKBASE IMPACTS

Sheet Bank Profile
B1: Bank Profile
B3: BANK IDENTITY
B4: Bank Name | C4: Navy Federal Investment Services (NFIS)
B5: Country
B6: Currency | C6: USD
B7: Stock Ticker | C7: N/A
B8: Report Year
B9: Data Sources
B11: Market Context Status | C11: NOT_RUN
B13: KEY FINANCIAL METRICS
B14: Metric | C14: Value | D14: Confidence | E14: Source
B15: Total NFCU Members | C15: 14000000 | D15: HIGH | E15: Discovery (E1)
B16: DI Members | C16: 115000 | D16: HIGH | E16: Discovery (E1)
B17: DI Penetration | C17: 0.82% | D17: HIGH | E17: Derived: 115K/14M
B18: Total DI AUM | C18: $500M | D18: HIGH | E18: Discovery (E3)
B19: Total NFIS AUA (incl FA) | C19: $7.4B | D19: HIGH | E19: Discovery (E3)
B20: Avg DI AUM | C20: $4,350 | D20: MEDIUM | E20: Derived: $500M/115K
B21: Robo Fee Rate | C21: 0.275% | D21: MEDIUM | E21: Discovery context
B22: SD Monthly Fee | C22: $3.50/mo | D22: MEDIUM | E22: Discovery (E18)
B23: Robo:SD Preference | C23: 2:1 | D23: HIGH | E23: Discovery (E6)
B24: Member Satisfaction | C24: 58% | D24: HIGH | E24: Discovery (E2)
B25: Funding Rate | C25: ~50% | D25: HIGH | E25: Discovery (E5, E21)
B26: Recurring Deposit Adoption | C26: 18% | D26: HIGH | E26: Discovery (E75)
B27: Daily Chat Volume | C27: 130 | D27: HIGH | E27: Discovery (E38, E91)
B28: Chat AHT | C28: 12m41s | D28: HIGH | E28: Discovery (E91)
B29: Monthly Email Volume | C29: 900-1000 | D29: HIGH | E29: Discovery (E92)
B30: Doc Rejection Rate | C30: 50% | D30: HIGH | E30: Discovery (E93)
B31: DI Growth Target | C31: 800K by 2030 | D31: HIGH | E31: Discovery (E1)
B32: Satisfaction Target | C32: 75% | D32: HIGH | E32: Discovery (E2)
B34: ADDITIONAL CONTEXT (Annual Report / Market Research)
B35: Metric | C35: Value | D35: Confidence | E35: Source
B36: Total NFIS AUA | C36: $7.4B | D36: HIGH | E36: Discovery (E3)
B37: FA-Side AUA | C37: $6.9B | D37: HIGH | E37: Derived: $7.4B - $500M
B38: Custodian Migration | C38: Apex (upcoming) | D38: HIGH | E38: Discovery (E81)
B39: Current Platform | C39: Fusion IQ | D39: HIGH | E39: Discovery (E89)
B40: NSF Events | C40: ~300/day | D40: HIGH | E40: Discovery (E24)
B41: 30-Day Closure Rate | C41: 10% | D41: HIGH | E41: Discovery (E4)
B42: Backend Systems | C42: DriveHub, DriveWell, Outlook (3 systems) | D42: HIGH | E42: Discovery (E107)
B44: DATA GAPS
B45: Data Needed | C45: Priority | D45: Impact | E45: Where to Obtain
...

Sheet Assumptions
B1: Assumptions Register
B3: All assumptions documented with sources and validation owners
B5: ID | C5: Assumption | D5: Value | E5: Conf. | F5: Source | G5: Owner | H5: Sensitivity
B6: A1 | C6: NFCU eligible member base for DI is 14M total members | E6: HIGH
B7: A2 | C7: CU investing penetration benchmark of 3% (conservative end of 3-5% range) | E7: MEDIUM
B8: A3 | C8: Average initial AUM for banking cross-sell accounts is $10,000 | E8: MEDIUM
B9: A4 | C9: Annual new DI account opens: 40,000/yr | E9: MEDIUM
B10: A5 | C10: Average initial funding amount: $5,000 | E10: LOW
B11: A6 | C11: Annual DI attrition rate: 7% | E11: LOW
B12: A7 | C12: 7% of DI members have AUM above FA threshold ($50K+) | E12: LOW
B13: A8 | C13: FA advisory fee rate: 0.65% (65 bps) | E13: LOW
B14: A9 | C14: Blended NFIS fee rate across DI + FA: 0.30% (30 bps) | E14: LOW
B15: A10 | C15: IRA withdrawals: ~200/month (2,400/yr) at 2 hours processing each | E15: LOW
B16: A11 | C16: Annual document submissions: 2,000 | E16: LOW
B17: A12 | C17: ACAT transfer attempts: 500/year | E17: LOW
... B19: A14 | C19: Addressable manual processing cost per onboarding: $50 | E19: LOW

Sheet Data Gaps
B1: Data Gaps — Required for Validation
B3: These data points are CRITICAL for validating the ROI model.
B5: ID | C5: Data Needed | D5: Priority | E5: Source | F5: Impact on Model
B6: DG-001 | C6: Annual NFIS revenue | D6: HIGH | E6: NFIS Finance | F6: Cannot validate <5% revenue check
B7: DG-002 | C7: Annual new DI account opens | D7: HIGH | E7: NFIS Operations | F7: L2 and CL5 baseline accuracy
B8: DG-003 | C8: Service team FTE count | D8: HIGH | E8: Tyler (Service Manager) | F8: L8 validation — current model uses volume-based cost
B9: DG-004 | C9: Actual DI attrition rate | D9: MEDIUM | E9: NFIS Analytics / TWB model output | F9: L7 baseline accuracy
B10: DG-005 | C10: FA advisor headcount | D10: MEDIUM | E10: Patrick Bryan | F10: CL1 capacity validation
B11: DG-006 | C11: FA fee rate schedule | D11: MEDIUM | E11: NFIS Product/Pricing | F11: L4 fee delta accuracy
B12: DG-007 | C12: Fusion IQ contract value | D12: MEDIUM | E12: NFIS IT/Procurement | F12: CL3 excluded without this data
B13: DG-008 | C13: AUM distribution of DI members | D13: MEDIUM | E13: NFIS Analytics | F13: L4 eligible population accuracy
B14: DG-009 | C14: IRA withdrawal volume and processing time | D14: LOW | E14: Tyler's team | F14: L8 IRA component
B15: DG-010 | C15: ACAT annual volume | D15: LOW | E15: NFIS Operations | F15: L5 (small lever)
